Workbook

Sheet Summary
A1: Unit-3 AE&JE Performance Matrix
A2: LINE-A&B DEC-25 | E2: 50 | F2: 5 | G2: 5 | H2: 10 | I2: 10 | J2: 10 | K2: 10 | L2: =SUM(E2:K2) -> 100
A3: Shift manager | B3: Sl no | C3: ID No | D3: Name | E3: Prodn Performance | F3: Attendence | G3: Punchuality | H3: Rejections | I3: 5S | J3: Safety & PPE Usage | K3: Disclipline | L3: Total
A4: Pradeep RS | B4: 1 | C4: 15205 | D4: S Rakesh | E4: ='15205'!H37 -> 25.617333 | F4: ='15205'!I37 -> 5 | G4: ='15205'!J37 -> 5 | H4: ='15205'!K37 -> 10 | I4: ='15205'!L37 -> 9.2 | J4: ='15205'!M37 -> 10 | K4: ='15205'!N37 -> 10 | L4: =SUM(E4:K4) -> 74.817333
A5: Pradeep RS | B5: 2 | C5: 1589 | D5: Bindhu sagar | E5: ='1589'!H37 -> 26.092857 | F5: ='1589'!I37 -> 5 | G5: ='1589'!J37 -> 5 | H5: ='1589'!K37 -> 10 | I5: ='1589'!L37 -> 9.1904762 | J5: ='1589'!M37 -> 10 | K5: ='1589'!N37 -> 10 | L5: =SUM(E5:K5) -> 75.283333
A6: Pradeep RS | B6: 3 | C6: 15325 | D6: Venkatesh Prasad G | E6: ='15325'!H37 -> 32.948485 | F6: ='15325'!I37 -> 5 | G6: ='15325'!J37 -> 5 | H6: ='15325'!K37 -> 10 | I6: ='15325'!L37 -> 9.1363636 | J6: ='15325'!M37 -> 10 | K6: ='15325'!N37 -> 10 | L6: =SUM(E6:K6) -> 82.084848
A7: Pradeep RS | B7: 4 | C7: 15010 | D7: TANMOY BERA | E7: ='15010'!H37 -> 29.532051 | F7: ='15010'!I37 -> 5 | G7: ='15010'!J37 -> 5 | H7: ='15010'!K37 -> 10 | I7: ='15010'!L37 -> 9.1923077 | J7: ='15010'!M37 -> 10 | K7: ='15010'!N37 -> 10 | L7: =SUM(E7:K7) -> 78.724359
A8: Pradeep RS | B8: 5 | C8: 15030 | D8: HASAN S K | E8: ='15030'!H37 -> 29.532051 | F8: ='15030'!I37 -> 5 | G8: ='15030'!J37 -> 5 | H8: ='15030'!K37 -> 10 | I8: ='15030'!L37 -> 9.1923077 | J8: ='15030'!M37 -> 10 | K8: ='15030'!N37 -> 10 | L8: =SUM(E8:K8) -> 78.724359
A9: Pradeep RS | B9: 6 | C9: 15096 | D9: Suman Samaddar | E9: ='15096'!H37 -> 24.289583 | F9: ='15096'!I37 -> 5 | G9: ='15096'!J37 -> 5 | H9: ='15096'!K37 -> 10 | I9: ='15096'!L37 -> 9.375 | J9: ='15096'!M37 -> 10 | K9: ='15096'!N37 -> 10 | L9: =SUM(E9:K9) -> 73.664583
A10: Pradeep RS | B10: 7 | C10: 15359 | D10: S MANOJ | E10: ='15359'!H37 -> 29.869298 | F10: ='15359'!I37 -> 5 | G10: ='15359'!J37 -> 5 | H10: ='15359'!K37 -> 10 | I10: ='15359'!L37 -> 9.1052632 | J10: ='15359'!M37 -> 10 | K10: ='15359'!N37 -> 10 | L10: =SUM(E10:K10) -> 78.974561
A11: Pradeep RS | B11: 8 | C11: 15532 | D11: Chandan M R | E11: ='15532'!H37 -> 29.532051 | F11: ='15532'!I37 -> 5 | G11: ='15532'!J37 -> 4.6153846 | H11: ='15532'!K37 -> 10 | I11: ='15532'!L37 -> 9.1923077 | J11: ='15532'!M37 -> 10 | K11: ='15532'!N37 -> 10 | L11: =SUM(E11:K11) -> 78.339744
A12: Pradeep RS | B12: 9 | C12: 15338 | D12: Prashanth R | E12: ='15338'!H37 -> 31.838 | F12: ='15338'!I37 -> 5 | G12: ='15338'!J37 -> 5 | H12: ='15338'!K37 -> 10 | I12: ='15338'!L37 -> 9.16 | J12: ='15338'!M37 -> 10 | K12: ='15338'!N37 -> 10 | L12: =SUM(E12:K12) -> 80.998
A13: Pradeep RS | B13: 10 | C13: 15529 | D13: Srinivasa V | E13: ='15529'!H37 -> 29.786 | F13: ='15529'!I37 -> 5 | G13: ='15529'!J37 -> 5 | H13: ='15529'!K37 -> 10 | I13: ='15529'!L37 -> 9.16 | J13: ='15529'!M37 -> 10 | K13: ='15529'!N37 -> 10 | L13: =SUM(E13:K13) -> 78.946
A14: Pradeep RS | B14: 11 | C14: 15098 | D14: Drashan Kumar | E14: ='15098'!H37 -> 29.851923 | F14: ='15098'!I37 -> 5 | G14: ='15098'!J37 -> 5 | H14: ='15098'!K37 -> 10 | I14: ='15098'!L37 -> 9.1923077 | J14: ='15098'!M37 -> 10 | K14: ='15098'!N37 -> 10 | L14: =SUM(E14:K14) -> 79.044231
A15: Pradeep RS | B15: 12 | C15: 15530 | D15: Poojarappa | E15: ='15530'!H37 -> 29.646 | F15: ='15530'!I37 -> 5 | G15: ='15530'!J37 -> 5 | H15: ='15530'!K37 -> 10 | I15: ='15530'!L37 -> 9.16 | J15: ='15530'!M37 -> 10 | K15: ='15530'!N37 -> 10 | L15: =SUM(E15:K15) -> 78.806
A16: Pradeep RS | B16: 13 | C16: 15326 | D16: Madhu sudhan | E16: ='15326'!H37 -> 29.851923 | F16: ='15326'!I37 -> 5 | G16: ='15326'!J37 -> 5 | H16: ='15326'!K37 -> 10 | I16: ='15326'!L37 -> 9.1923077 | J16: ='15326'!M37 -> 10 | K16: ='15326'!N37 -> 10 | L16: =SUM(E16:K16) -> 79.044231
A17: Pradeep RS | B17: 14 | C17: 15322 | D17: Bhojaraju K | E17: ='15322'!H37 -> 37.248611 | F17: ='15322'!I37 -> 5 | G17: ='15322'!J37 -> 5 | H17: ='15322'!K37 -> 10 | I17: ='15322'!L37 -> 9.1538462 | J17: ='15322'!M37 -> 10 | K17: ='15322'!N37 -> 10 | L17: =SUM(E17:K17) -> 86.402457
A18: Pradeep RS | B18: 15 | C18: 15539 | D18: Kempanna VR | E18: ='15539'!H37 -> 32.493478 | F18: ='15539'!I37 -> 5 | G18: ='15539'!J37 -> 5 | H18: ='15539'!K37 -> 10 | I18: ='15539'!L37 -> 9.3043478 | J18: ='15539'!M37 -> 10 | K18: ='15539'!N37 -> 10 | L18: =SUM(E18:K18) -> 81.797826
A19: Pradeep RS | B19: 16 | C19: 15362 | D19: Hemantha Kumar R N | E19: ='15362'!H37 -> 33.104861 | F19: ='15362'!I37 -> 5 | G19: ='15362'!J37 -> 5 | H19: ='15362'!K37 -> 10 | I19: ='15362'!L37 -> 9.2083333 | J19: ='15362'!M37 -> 10 | K19: ='15362'!N37 -> 10 | L19: =SUM(E19:K19) -> 82.313194
A20: Pradeep RS | B20: 17 | C20: 15008 | D20: Manikandan | E20: ='15008'!H37 -> 26.555128 | F20: ='15008'!I37 -> 5 | G20: ='15008'!J37 -> 5 | H20: ='15008'!K37 -> 10 | I20: ='15008'!L37 -> 9.1923077 | J20: ='15008'!M37 -> 10 | K20: ='15008'!N37 -> 10 | L20: =SUM(E20:K20) -> 75.747436
A21: Pradeep RS | B21: 18 | C21: 15340 | D21: Sachidnand Sagar G D | E21: ='15340'!H37 -> 26.5 | F21: ='15340'!I37 -> 5 | G21: ='15340'!J37 -> 5 | H21: ='15340'!K37 -> 10 | I21: ='15340'!L37 -> 9.2307692 | J21: ='15340'!M37 -> 10 | K21: ='15340'!N37 -> 10 | L21: =SUM(E21:K21) -> 75.730769
A22: ANIL KUMAR S | B22: 19 | C22: 1572/A | D22: Muttanna Mulimani | E22: ='1572A'!H37 -> 32.573485 | F22: ='1572A'!I37 -> 5 | G22: ='1572A'!J37 -> 5 | H22: ='1572A'!K37 -> 10 | I22: ='1572A'!L37 -> 9.2272727 | J22: ='1572A'!M37 -> 10 | K22: ='1572A'!N37 -> 10 | L22: =SUM(E22:K22) -> 81.800758
A23: ANIL KUMAR S | B23: 20 | C23: 15237 | D23: Abhishek K | E23: ='15237'!H37 -> 36.545833 | F23: ='15237'!I37 -> 5 | G23: ='15237'!J37 -> 5 | H23: ='15237'!K37 -> 10 | I23: ='15237'!L37 -> 9.1666667 | J23: ='15237'!M37 -> 10 | K23: ='15237'!N37 -> 10 | L23: =SUM(E23:K23) -> 85.7125
A24: ANIL KUMAR S | B24: 21 | C24: 15203 | D24: Varaprasad | E24: ='15203'!H37 -> 34.481333 | F24: ='15203'!I37 -> 5 | G24: ='15203'!J37 -> 5 | H24: ='15203'!K37 -> 10 | I24: ='15203'!L37 -> 9.2 | J24: ='15203'!M37 -> 10 | K24: ='15203'!N37 -> 10 | L24: =SUM(E24:K24) -> 83.681333
A25: ANIL KUMAR S | B25: 22 | C25: 15045 | D25: Digamber | E25: ='15045'!H37 -> 35.32 | F25: ='15045'!I37 -> 5 | G25: ='15045'!J37 -> 5 | H25: ='15045'!K37 -> 10 | I25: ='15045'!L37 -> 9.2 | J25: ='15045'!M37 -> 10 | K25: ='15045'!N37 -> 10 | L25: =SUM(E25:K25) -> 84.52
A26: ANIL KUMAR S | B26: 23 | C26: 15128 | D26: Prabath kumar | E26: ='15128'!H37 -> 35.784 | F26: ='15128'!I37 -> 5 | G26: ='15128'!J37 -> 5 | H26: ='15128'!K37 -> 10 | I26: ='15128'!L37 -> 9.24 | J26: ='15128'!M37 -> 10 | K26: ='15128'!N37 -> 10 | L26: =SUM(E26:K26) -> 85.024
A27: ANIL KUMAR S | B27: 24 | C27: 15542 | D27: Rakaeh kumar | E27: ='15542'!H37 -> 35.694 | F27: ='15542'!I37 -> 5 | G27: ='15542'!J37 -> 5 | H27: ='15542'!K37 -> 10 | I27: ='15542'!L37 -> 9.16 | J27: ='15542'!M37 -> 10 | K27: ='15542'!N37 -> 10 | L27: =SUM(E27:K27) -> 84.854
A28: ANIL KUMAR S | B28: 25 | C28: 15538 | D28: Rajat Kumar Malik | E28: ='15538'!H37 -> 35.688 | F28: ='15538'!I37 -> 5 | G28: ='15538'!J37 -> 5 | H28: ='15538'!K37 -> 10 | I28: ='15538'!L37 -> 9.2 | J28: ='15538'!M37 -> 10 | K28: ='15538'!N37 -> 10 | L28: =SUM(E28:K28) -> 84.888
A29: ANIL KUMAR S | B29: 26 | C29: 15027 | D29: Brajesh kumar | E29: ='15027'!H37 -> 35.746667 | F29: ='15027'!I37 -> 5 | G29: ='15027'!J37 -> 5 | H29: ='15027'!K37 -> 10 | I29: ='15027'!L37 -> 9.2 | J29: ='15027'!M37 -> 10 | K29: ='15027'!N37 -> 10 | L29: =SUM(E29:K29) -> 84.946667
A30: ANIL KUMAR S | B30: 27 | C30: 15360 | D30: Ravi kumar | E30: ='15360'!H37 -> 38.725 | F30: ='15360'!I37 -> 5 | G30: ='15360'!J37 -> 5 | H30: ='15360'!K37 -> 10 | I30: ='15360'!L37 -> 9.2222222 | J30: ='15360'!M37 -> 10 | K30: ='15360'!N37 -> 10 | L30: =SUM(E30:K30) -> 87.947222
A31: ANIL KUMAR S | B31: 28 | C31: 15342 | D31: Punith kumar BN | E31: ='15342'!H37 -> 34.520513 | F31: ='15342'!I37 -> 5 | G31: ='15342'!J37 -> 5 | H31: ='15342'!K37 -> 10 | I31: ='15342'!L37 -> 9.1923077 | J31: ='15342'!M37 -> 10 | K31: ='15342'!N37 -> 10 | L31: =SUM(E31:K31) -> 83.712821
A32: ANIL KUMAR S | B32: 29 | C32: 15038 | D32: Subrath kumar | E32: ='15038'!H37 -> 31.933974 | F32: ='15038'!I37 -> 5 | G32: ='15038'!J37 -> 5 | H32: ='15038'!K37 -> 10 | I32: ='15038'!L37 -> 9.1923077 | J32: ='15038'!M37 -> 10 | K32: ='15038'!N37 -> 10 | L32: =SUM(E32:K32) -> 81.126282
A33: ANIL KUMAR S | B33: 30 | C33: 15543 | D33: Anil H | E33: ='15543'!H37 -> 31.933974 | F33: ='15543'!I37 -> 5 | G33: ='15543'!J37 -> 5 | H33: ='15543'!K37 -> 10 | I33: ='15543'!L37 -> 9.1923077 | J33: ='15543'!M37 -> 10 | K33: ='15543'!N37 -> 10 | L33: =SUM(E33:K33) -> 81.126282

Sheet 15030
A1: Employee Performance Report | P1: REMARKS
A2: ID No | B2: Name | C2: Shift | D2: Stage | E2: Line | F2: Target | G2: Actual | H2: Matrix
A3: 15030 | B3: HASAN SK
H4: 50 | I4: 5 | J4: 5 | K4: 10 | L4: 10 | M4: 10 | N4: 10 | O4: =SUM(H4:N4) -> 100
A5: Sl No | B5: Date | H5: Prodn Performance | I5: Attendence | J5: Punchuality | K5: Rejections | L5: 5S | M5: Safety & PPE Usage | N5: Disclipline | O5: Total
A6: 1 | B6: 45992 | C6: S3 | D6: STRINGER | E6: A | F6: 1000 | G6: 605 | H6: =G6/F6*50 -> 30.25 | I6: 5 | J6: 5 | K6: 10 | L6: 10 | M6: 10 | N6: 10 | O6: =SUM(H6:N6) -> 80.25
A7: 2 | B7: 45993 | C7: S3 | D7: STRINGER | E7: A | F7: 1000 | G7: 693 | H7: =G7/F7*50 -> 34.65 | I7: 5 | J7: 5 | K7: 10 | L7: 9 | M7: 10 | N7: 10 | O7: =SUM(H7:N7) -> 83.65
A8: 3 | B8: 45994 | C8: S3 | D8: STRINGER | E8: A | F8: 1000 | G8: 698 | H8: =G8/F8*50 -> 34.9 | I8: 5 | J8: 5 | K8: 10 | L8: 10 | M8: 10 | N8: 10 | O8: =SUM(H8:N8) -> 84.9
A9: 4 | B9: 45995 | C9: S3 | D9: STRINGER | E9: A | F9: 1000 | G9: 714 | H9: =G9/F9*50 -> 35.7 | I9: 5 | J9: 5 | K9: 10 | L9: 7 | M9: 10 | N9: 10 | O9: =SUM(H9:N9) -> 82.7
A10: 5 | B10: 45996 | C10: S3 | D10: STRINGER | E10: A | F10: 1500 | G10: 707 | H10: =G10/F10*50 -> 23.566667 | I10: 5 | J10: 5 | K10: 10 | L10: 9 | M10: 10 | N10: 10 | O10: =SUM(H10:N10) -> 72.566667
A11: 6 | B11: 45997 | C11: S3 | D11: STRINGER | E11: A | F11: 1500 | G11: 129 | H11: =G11/F11*50 -> 4.3 | I11: 5 | J11: 5 | K11: 10 | L11: 9 | M11: 10 | N11: 10 | O11: =SUM(H11:N11) -> 53.3
A12: 7 | B12: 45998 | C12: W/O
A13: 8 | B13: 45999 | C13: S2 | D13: STRINGER | E13: A | F13: 1000 | G13: 693 | H13: =G13/F13*50 -> 34.65 | I13: 5 | J13: 5 | K13: 10 | L13: 9 | M13: 10 | N13: 10 | O13: =SUM(H13:N13) -> 83.65
A14: 9 | B14: 46000 | C14: S2 | D14: STRINGER | E14: A | F14: 1000 | G14: 543 | H14: =G14/F14*50 -> 27.15 | I14: 5 | J14: 5 | K14: 10 | L14: 10 | M14: 10 | N14: 10 | O14: =SUM(H14:N14) -> 77.15
A15: 10 | B15: 46001 | C15: S2 | D15: STRINGER | E15: A | F15: 1000 | G15: 608 | H15: =G15/F15*50 -> 30.4 | I15: 5 | J15: 5 | K15: 10 | L15: 10 | M15: 10 | N15: 10 | O15: =SUM(H15:N15) -> 80.4
A16: 11 | B16: 46002 | C16: S2 | D16: STRINGER | E16: A | F16: 579 | G16: 579 | H16: =G16/F16*50 -> 50 | I16: 5 | J16: 5 | K16: 10 | L16: 9 | M16: 10 | N16: 10 | O16: =SUM(H16:N16) -> 99 | P16: System hanging issue
A17: 12 | B17: 46003 | C17: W/O
A18: 13 | B18: 46004 | C18: S1 | D18: STRINGER | E18: A | F18: 1500 | G18: 921 | H18: =G18/F18*50 -> 30.7 | I18: 5 | J18: 5 | K18: 10 | L18: 9 | M18: 10 | N18: 10 | O18: =SUM(H18:N18) -> 79.7
A19: 14 | B19: 46005 | C19: S1 | D19: STRINGER | E19: A | F19: 1500 | G19: 387 | H19: =G19/F19*50 -> 12.9 | I19: 5 | J19: 5 | K19: 10 | L19: 9 | M19: 10 | N19: 10 | O19: =SUM(H19:N19) -> 61.9
A20: 15 | B20: 46006 | C20: S1 | D20: STRINGER | E20: A | F20: 1000 | G20: 599 | H20: =G20/F20*50 -> 29.95 | I20: 5 | J20: 5 | K20: 10 | L20: 8 | M20: 10 | N20: 10 | O20: =SUM(H20:N20) -> 77.95
A21: 16 | B21: 46007 | C21: S1 | D21: STRINGER | E21: A | F21: 513 | G21: 513 | H21: =G21/F21*50 -> 50 | I21: 5 | J21: 5 | K21: 10 | L21: 8 | M21: 10 | N21: 10 | O21: =SUM(H21:N21) -> 98 | P21: Display not working
A22: 17 | B22: 46008 | C22: S1 | D22: STRINGER | E22: A | F22: 1000 | G22: 682 | H22: =G22/F22*50 -> 34.1 | I22: 5 | J22: 5 | K22: 10 | L22: 10 | M22: 10 | N22: 10 | O22: =SUM(H22:N22) -> 84.1
A23: 18 | B23: 46009 | C23: S1 | D23: STRINGER | E23: A | F23: 1000 | G23: 765 | H23: =G23/F23*50 -> 38.25 | I23: 5 | J23: 5 | K23: 10 | L23: 10 | M23: 10 | N23: 10 | O23: =SUM(H23:N23) -> 88.25
A24: 19 | B24: 46010 | C24: S1 | D24: STRINGER | E24: A | F24: 1085 | G24: 1085 | H24: =G24/F24*50 -> 50 | I24: 5 | J24: 5 | K24: 10 | L24: 9 | M24: 10 | N24: 10 | O24: =SUM(H24:N24) -> 99 | P24: Aside stopped due to IR lamp issue
A25: 20 | B25: 46011 | C25: W/O
A26: 21 | B26: 46012 | C26: S3 | D26: STRINGER | E26: A | F26: 1500 | G26: 882 | H26: =G26/F26*50 -> 29.4 | I26: 5 | J26: 5 | K26: 10 | L26: 9 | M26: 10 | N26: 10 | O26: =SUM(H26:N26) -> 78.4
A27: 22 | B27: 46013 | C27: S3 | D27: STRINGER | E27: A | F27: 1000 | G27: 0 | H27: =G27/F27*50 -> 0 | I27: 5 | J27: 5 | K27: 10 | L27: 10 | M27: 10 | N27: 10 | O27: =SUM(H27:N27) -> 50
A28: 23 | B28: 46014 | C28: S3 | D28: STRINGER | E28: A | F28: 1000 | G28: 510 | H28: =G28/F28*50 -> 25.5 | I28: 5 | J28: 5 | K28: 10 | L28: 10 | M28: 10 | N28: 10 | O28: =SUM(H28:N28) -> 75.5
A29: 24 | B29: 46015 | C29: S3 | D29: STRINGER | E29: A | F29: 1000 | G29: 650 | H29: =G29/F29*50 -> 32.5 | I29: 5 | J29: 5 | K29: 10 | L29: 9 | M29: 10 | N29: 10 | O29: =SUM(H29:N29) -> 81.5
A30: 25 | B30: 46016 | C30: S3 | D30: STRINGER | E30: A | F30: 1000 | G30: 743 | H30: =G30/F30*50 -> 37.15 | I30: 5 | J30: 5 | K30: 10 | L30: 10 | M30: 10 | N30: 10 | O30: =SUM(H30:N30) -> 87.15
A31: 26 | B31: 46017 | C31: S3 | D31: STRINGER | E31: A | F31: 1500 | G31: 1041 | H31: =G31/F31*50 -> 34.7 | I31: 5 | J31: 5 | K31: 10 | L31: 8 | M31: 10 | N31: 10 | O31: =SUM(H31:N31) -> 82.7
A32: 27 | B32: 46018 | C32: S3 | D32: STRINGER | E32: A | F32: 1500 | G32: 335 | H32: =G32/F32*50 -> 11.166667 | I32: 5 | J32: 5 | K32: 10 | L32: 9 | M32: 10 | N32: 10 | O32: =SUM(H32:N32) -> 60.166667
A33: 28 | B33: 46019 | C33: W/O
A34: 29 | B34: 46020 | C34: S2 | D34: STRINGER | E34: A | F34: 1000 | G34: 441 | H34: =G34/F34*50 -> 22.05 | I34: 5 | J34: 5 | K34: 10 | L34: 9 | M34: 10 | N34: 10 | O34: =SUM(H34:N34) -> 71.05
A35: 30 | B35: 46021 | C35: S2 | D35: STRINGER | E35: A | F35: 1000 | G35: 478 | H35: =G35/F35*50 -> 23.9 | I35: 5 | J35: 5 | K35: 10 | L35: 10 | M35: 10 | N35: 10 | O35: =SUM(H35:N35) -> 73.9
A36: 31 | B36: 46022 | C36: S2 | D36: STRINGER | E36: A | F36: 1000 | G36: 510 | H36: =G36/F36*50 -> 25.5 | I36: 5 | J36: 5 | K36: 10 | L36: 10 | M36: 10 | N36: 10 | O36: =SUM(H36:N36) -> 75.5
G37: TOTAL | H37: =AVERAGE(H6:H35) -> 29.532051 | I37: =AVERAGE(I6:I35) -> 5 | J37: =AVERAGE(J6:J35) -> 5 | K37: =AVERAGE(K6:K35) -> 10 | L37: =AVERAGE(L6:L35) -> 9.1923077 | M37: =AVERAGE(M6:M35) -> 10 | N37: =AVERAGE(N6:N35) -> 10 | O37: =SUM(H37:N37) -> 78.724359

Sheet 15010
A1: Employee Performance Report | P1: REMARKS
A2: ID No | B2: Name | C2: Shift | D2: Stage | E2: Line | F2: Target | G2: Actual | H2: Matrix
A3: 15010 | B3: TANMOY BERA
H4: 50 | I4: 5 | J4: 5 | K4: 10 | L4: 10 | M4: 10 | N4: 10 | O4: =SUM(H4:N4) -> 100
A5: Sl No | B5: Date | H5: Prodn Performance | I5: Attendence | J5: Punchuality | K5: Rejections | L5: 5S | M5: Safety & PPE Usage | N5: Disclipline | O5: Total
A6: 1 | B6: 45992 | C6: S3 | D6: STRINGER | E6: B | F6: 1000 | G6: 605 | H6: =G6/F6*50 -> 30.25 | I6: 5 | J6: 5 | K6: 10 | L6: 10 | M6: 10 | N6: 10 | O6: =SUM(H6:N6) -> 80.25
A7: 2 | B7: 45993 | C7: S3 | D7: STRINGER | E7: B | F7: 1000 | G7: 693 | H7: =G7/F7*50 -> 34.65 | I7: 5 | J7: 5 | K7: 10 | L7: 9 | M7: 10 | N7: 10 | O7: =SUM(H7:N7) -> 83.65
A8: 3 | B8: 45994 | C8: S3 | D8: STRINGER | E8: B | F8: 1000 | G8: 698 | H8: =G8/F8*50 -> 34.9 | I8: 5 | J8: 5 | K8: 10 | L8: 10 | M8: 10 | N8: 10 | O8: =SUM(H8:N8) -> 84.9
A9: 4 | B9: 45995 | C9: S3 | D9: STRINGER | E9: B | F9: 1000 | G9: 714 | H9: =G9/F9*50 -> 35.7 | I9: 5 | J9: 5 | K9: 10 | L9: 7 | M9: 10 | N9: 10 | O9: =SUM(H9:N9) -> 82.7
A10: 5 | B10: 45996 | C10: S3 | D10: STRINGER | E10: B | F10: 1500 | G10: 707 | H10: =G10/F10*50 -> 23.566667 | I10: 5 | J10: 5 | K10: 10 | L10: 9 | M10: 10 | N10: 10 | O10: =SUM(H10:N10) -> 72.566667
A11: 6 | B11: 45997 | C11: S3 | D11: STRINGER | E11: B | F11: 1500 | G11: 129 | H11: =G11/F11*50 -> 4.3 | I11: 5 | J11: 5 | K11: 10 | L11: 9 | M11: 10 | N11: 10 | O11: =SUM(H11:N11) -> 53.3
A12: 7 | B12: 45998 | C12: W/O
A13: 8 | B13: 45999 | C13: S2 | D13: STRINGER | E13: B | F13: 1000 | G13: 693 | H13: =G13/F13*50 -> 34.65 | I13: 5 | J13: 5 | K13: 10 | L13: 9 | M13: 10 | N13: 10 | O13: =SUM(H13:N13) -> 83.65
A14: 9 | B14: 46000 | C14: S2 | D14: STRINGER | E14: B | F14: 1000 | G14: 543 | H14: =G14/F14*50 -> 27.15 | I14: 5 | J14: 5 | K14: 10 | L14: 10 | M14: 10 | N14: 10 | O14: =SUM(H14:N14) -> 77.15
A15: 10 | B15: 46001 | C15: S2 | D15: STRINGER | E15: B | F15: 1000 | G15: 608 | H15: =G15/F15*50 -> 30.4 | I15: 5 | J15: 5 | K15: 10 | L15: 10 | M15: 10 | N15: 10 | O15: =SUM(H15:N15) -> 80.4
A16: 11 | B16: 46002 | C16: S2 | D16: STRINGER | E16: B | F16: 579 | G16: 579 | H16: =G16/F16*50 -> 50 | I16: 5 | J16: 5 | K16: 10 | L16: 9 | M16: 10 | N16: 10 | O16: =SUM(H16:N16) -> 99 | P16: System hanging issue
A17: 12 | B17: 46003 | C17: W/O
A18: 13 | B18: 46004 | C18: S1 | D18: STRINGER | E18: B | F18: 1500 | G18: 921 | H18: =G18/F18*50 -> 30.7 | I18: 5 | J18: 5 | K18: 10 | L18: 9 | M18: 10 | N18: 10 | O18: =SUM(H18:N18) -> 79.7
A19: 14 | B19: 46005 | C19: S1 | D19: STRINGER | E19: B | F19: 1500 | G19: 387 | H19: =G19/F19*50 -> 12.9 | I19: 5 | J19: 5 | K19: 10 | L19: 9 | M19: 10 | N19: 10 | O19: =SUM(H19:N19) -> 61.9
A20: 15 | B20: 46006 | C20: S1 | D20: STRINGER | E20: B | F20: 1000 | G20: 599 | H20: =G20/F20*50 -> 29.95 | I20: 5 | J20: 5 | K20: 10 | L20: 8 | M20: 10 | N20: 10 | O20: =SUM(H20:N20) -> 77.95
A21: 16 | B21: 46007 | C21: S1 | D21: STRINGER | E21: B | F21: 513 | G21: 513 | H21: =G21/F21*50 -> 50 | I21: 5 | J21: 5 | K21: 10 | L21: 8 | M21: 10 | N21: 10 | O21: =SUM(H21:N21) -> 98 | P21: Display not working
A22: 17 | B22: 46008 | C22: S1 | D22: STRINGER | E22: B | F22: 1000 | G22: 682 | H22: =G22/F22*50 -> 34.1 | I22: 5 | J22: 5 | K22: 10 | L22: 10 | M22: 10 | N22: 10 | O22: =SUM(H22:N22) -> 84.1
A23: 18 | B23: 46009 | C23: S1 | D23: STRINGER | E23: B | F23: 1000 | G23: 765 | H23: =G23/F23*50 -> 38.25 | I23: 5 | J23: 5 | K23: 10 | L23: 10 | M23: 10 | N23: 10 | O23: =SUM(H23:N23) -> 88.25
A24: 19 | B24: 46010 | C24: S1 | D24: STRINGER | E24: B | F24: 1085 | G24: 1085 | H24: =G24/F24*50 -> 50 | I24: 5 | J24: 5 | K24: 10 | L24: 9 | M24: 10 | N24: 10 | O24: =SUM(H24:N24) -> 99 | P24: Aside stopped due to IR lamp issue
A25: 20 | B25: 46011 | C25: W/O
A26: 21 | B26: 46012 | C26: S3 | D26: STRINGER | E26: B | F26: 1500 | G26: 882 | H26: =G26/F26*50 -> 29.4 | I26: 5 | J26: 5 | K26: 10 | L26: 9 | M26: 10 | N26: 10 | O26: =SUM(H26:N26) -> 78.4
A27: 22 | B27: 46013 | C27: S3 | D27: STRINGER | E27: B | F27: 1000 | G27: 0 | H27: =G27/F27*50 -> 0 | I27: 5 | J27: 5 | K27: 10 | L27: 10 | M27: 10 | N27: 10 | O27: =SUM(H27:N27) -> 50
A28: 23 | B28: 46014 | C28: S3 | D28: STRINGER | E28: B | F28: 1000 | G28: 510 | H28: =G28/F28*50 -> 25.5 | I28: 5 | J28: 5 | K28: 10 | L28: 10 | M28: 10 | N28: 10 | O28: =SUM(H28:N28) -> 75.5
A29: 24 | B29: 46015 | C29: S3 | D29: STRINGER | E29: B | F29: 1000 | G29: 650 | H29: =G29/F29*50 -> 32.5 | I29: 5 | J29: 5 | K29: 10 | L29: 9 | M29: 10 | N29: 10 | O29: =SUM(H29:N29) -> 81.5
A30: 25 | B30: 46016 | C30: S3 | D30: STRINGER | E30: B | F30: 1000 | G30: 743 | H30: =G30/F30*50 -> 37.15 | I30: 5 | J30: 5 | K30: 10 | L30: 10 | M30: 10 | N30: 10 | O30: =SUM(H30:N30) -> 87.15
A31: 26 | B31: 46017 | C31: S3 | D31: STRINGER | E31: B | F31: 1500 | G31: 1041 | H31: =G31/F31*50 -> 34.7 | I31: 5 | J31: 5 | K31: 10 | L31: 8 | M31: 10 | N31: 10 | O31: =SUM(H31:N31) -> 82.7
A32: 27 | B32: 46018 | C32: S3 | D32: STRINGER | E32: B | F32: 1500 | G32: 335 | H32: =G32/F32*50 -> 11.166667 | I32: 5 | J32: 5 | K32: 10 | L32: 9 | M32: 10 | N32: 10 | O32: =SUM(H32:N32) -> 60.166667
A33: 28 | B33: 46019 | C33: W/O
A34: 29 | B34: 46020 | C34: S2 | D34: STRINGER | E34: B | F34: 1000 | G34: 441 | H34: =G34/F34*50 -> 22.05 | I34: 5 | J34: 5 | K34: 10 | L34: 9 | M34: 10 | N34: 10 | O34: =SUM(H34:N34) -> 71.05
A35: 30 | B35: 46021 | C35: S2 | D35: STRINGER | E35: B | F35: 1000 | G35: 478 | H35: =G35/F35*50 -> 23.9 | I35: 5 | J35: 5 | K35: 10 | L35: 10 | M35: 10 | N35: 10 | O35: =SUM(H35:N35) -> 73.9
A36: 31 | B36: 46022 | C36: S2 | D36: STRINGER | E36: B | F36: 1000 | G36: 510 | H36: =G36/F36*50 -> 25.5 | I36: 5 | J36: 5 | K36: 10 | L36: 10 | M36: 10 | N36: 10 | O36: =SUM(H36:N36) -> 75.5
G37: TOTAL | H37: =AVERAGE(H6:H35) -> 29.532051 | I37: =AVERAGE(I6:I35) -> 5 | J37: =AVERAGE(J6:J35) -> 5 | K37: =AVERAGE(K6:K35) -> 10 | L37: =AVERAGE(L6:L35) -> 9.1923077 | M37: =AVERAGE(M6:M35) -> 10 | N37: =AVERAGE(N6:N35) -> 10 | O37: =SUM(H37:N37) -> 78.724359

Sheet 15532
A1: Employee Performance Report | P1: REMARKS
A2: ID No | B2: Name | C2: Shift | D2: Stage | E2: Line | F2: Target | G2: Actual | H2: Matrix
A3: 15532 | B3: CHANDAN MR
H4: 50 | I4: 5 | J4: 5 | K4: 10 | L4: 10 | M4: 10 | N4: 10 | O4: =SUM(H4:N4) -> 100
A5: Sl No | B5: Date | H5: Prodn Performance | I5: Attendence | J5: Punchuality | K5: Rejections | L5: 5S | M5: Safety & PPE Usage | N5: Disclipline | O5: Total
A6: 1 | B6: 45992 | C6: S3 | D6: STRINGER | E6: A | F6: 1000 | G6: 605 | H6: =G6/F6*50 -> 30.25 | I6: 5 | J6: 5 | K6: 10 | L6: 10 | M6: 10 | N6: 10 | O6: =SUM(H6:N6) -> 80.25
A7: 2 | B7: 45993 | C7: S3 | D7: STRINGER | E7: A | F7: 1000 | G7: 693 | H7: =G7/F7*50 -> 34.65 | I7: 5 | J7: 5 | K7: 10 | L7: 9 | M7: 10 | N7: 10 | O7: =SUM(H7:N7) -> 83.65
A8: 3 | B8: 45994 | C8: S3 | D8: STRINGER | E8: A | F8: 1000 | G8: 698 | H8: =G8/F8*50 -> 34.9 | I8: 5 | J8: 5 | K8: 10 | L8: 10 | M8: 10 | N8: 10 | O8: =SUM(H8:N8) -> 84.9
A9: 4 | B9: 45995 | C9: S3 | D9: STRINGER | E9: A | F9: 1000 | G9: 714 | H9: =G9/F9*50 -> 35.7 | I9: 5 | J9: 5 | K9: 10 | L9: 7 | M9: 10 | N9: 10 | O9: =SUM(H9:N9) -> 82.7
A10: 5 | B10: 45996 | C10: S3 | D10: STRINGER | E10: A | F10: 1500 | G10: 707 | H10: =G10/F10*50 -> 23.566667 | I10: 5 | J10: 5 | K10: 10 | L10: 9 | M10: 10 | N10: 10 | O10: =SUM(H10:N10) -> 72.566667
A11: 6 | B11: 45997 | C11: S3 | D11: STRINGER | E11: A | F11: 1500 | G11: 129 | H11: =G11/F11*50 -> 4.3 | I11: 5 | J11: 5 | K11: 10 | L11: 9 | M11: 10 | N11: 10 | O11: =SUM(H11:N11) -> 53.3
A12: 7 | B12: 45998 | C12: W/O
A13: 8 | B13: 45999 | C13: S2 | D13: STRINGER | E13: A | F13: 1000 | G13: 693 | H13: =G13/F13*50 -> 34.65 | I13: 5 | J13: 5 | K13: 10 | L13: 9 | M13: 10 | N13: 10 | O13: =SUM(H13:N13) -> 83.65
A14: 9 | B14: 46000 | C14: S2 | D14: STRINGER | E14: A | F14: 1000 | G14: 543 | H14: =G14/F14*50 -> 27.15 | I14: 5 | J14: 5 | K14: 10 | L14: 10 | M14: 10 | N14: 10 | O14: =SUM(H14:N14) -> 77.15
A15: 10 | B15: 46001 | C15: S2 | D15: STRINGER | E15: A | F15: 1000 | G15: 608 | H15: =G15/F15*50 -> 30.4 | I15: 5 | J15: 5 | K15: 10 | L15: 10 | M15: 10 | N15: 10 | O15: =SUM(H15:N15) -> 80.4
A16: 11 | B16: 46002 | C16: S2 | D16: STRINGER | E16: A | F16: 579 | G16: 579 | H16: =G16/F16*50 -> 50 | I16: 5 | J16: 5 | K16: 10 | L16: 9 | M16: 10 | N16: 10 | O16: =SUM(H16:N16) -> 99 | P16: System hanging issue
A17: 12 | B17: 46003 | C17: W/O
A18: 13 | B18: 46004 | C18: S1 | D18: STRINGER | E18: A | F18: 1500 | G18: 921 | H18: =G18/F18*50 -> 30.7 | I18: 5 | J18: 5 | K18: 10 | L18: 9 | M18: 10 | N18: 10 | O18: =SUM(H18:N18) -> 79.7
A19: 14 | B19: 46005 | C19: S1 | D19: STRINGER | E19: A | F19: 1500 | G19: 387 | H19: =G19/F19*50 -> 12.9 | I19: 5 | J19: 5 | K19: 10 | L19: 9 | M19: 10 | N19: 10 | O19: =SUM(H19:N19) -> 61.9
A20: 15 | B20: 46006 | C20: S1 | D20: STRINGER | E20: A | F20: 1000 | G20: 599 | H20: =G20/F20*50 -> 29.95 | I20: 5 | J20: 0 | K20: 10 | L20: 8 | M20: 10 | N20: 10 | O20: =SUM(H20:N20) -> 72.95
A21: 16 | B21: 46007 | C21: S1 | D21: STRINGER | E21: A | F21: 513 | G21: 513 | H21: =G21/F21*50 -> 50 | I21: 5 | J21: 5 | K21: 10 | L21: 8 | M21: 10 | N21: 10 | O21: =SUM(H21:N21) -> 98 | P21: Display not working
A22: 17 | B22: 46008 | C22: S1 | D22: STRINGER | E22: A | F22: 1000 | G22: 682 | H22: =G22/F22*50 -> 34.1 | I22: 5 | J22: 5 | K22: 10 | L22: 10 | M22: 10 | N22: 10 | O22: =SUM(H22:N22) -> 84.1
A23: 18 | B23: 46009 | C23: S1 | D23: STRINGER | E23: A | F23: 1000 | G23: 765 | H23: =G23/F23*50 -> 38.25 | I23: 5 | J23: 5 | K23: 10 | L23: 10 | M23: 10 | N23: 10 | O23: =SUM(H23:N23) -> 88.25
A24: 19 | B24: 46010 | C24: S1 | D24: STRINGER | E24: A | F24: 1085 | G24: 1085 | H24: =G24/F24*50 -> 50 | I24: 5 | J24: 5 | K24: 10 | L24: 9 | M24: 10 | N24: 10 | O24: =SUM(H24:N24) -> 99 | P24: Aside stopped due to IR lamp issue
A25: 20 | B25: 46011 | C25: W/O
A26: 21 | B26: 46012 | C26: S3 | D26: STRINGER | E26: A | F26: 1500 | G26: 882 | H26: =G26/F26*50 -> 29.4 | I26: 5 | J26: 5 | K26: 10 | L26: 9 | M26: 10 | N26: 10 | O26: =SUM(H26:N26) -> 78.4
A27: 22 | B27: 46013 | C27: S3 | D27: STRINGER | E27: A | F27: 1000 | G27: 0 | H27: =G27/F27*50 -> 0 | I27: 5 | J27: 5 | K27: 10 | L27: 10 | M27: 10 | N27: 10 | O27: =SUM(H27:N27) -> 50
A28: 23 | B28: 46014 | C28: S3 | D28: STRINGER | E28: A | F28: 1000 | G28: 510 | H28: =G28/F28*50 -> 25.5 | I28: 5 | J28: 5 | K28: 10 | L28: 10 | M28: 10 | N28: 10 | O28: =SUM(H28:N28) -> 75.5
A29: 24 | B29: 46015 | C29: S3 | D29: STRINGER | E29: A | F29: 1000 | G29: 650 | H29: =G29/F29*50 -> 32.5 | I29: 5 | J29: 5 | K29: 10 | L29: 9 | M29: 10 | N29: 10 | O29: =SUM(H29:N29) -> 81.5
A30: 25 | B30: 46016 | C30: S3 | D30: STRINGER | E30: A | F30: 1000 | G30: 743 | H30: =G30/F30*50 -> 37.15 | I30: 5 | J30: 5 | K30: 10 | L30: 10 | M30: 10 | N30: 10 | O30: =SUM(H30:N30) -> 87.15
A31: 26 | B31: 46017 | C31: S3 | D31: STRINGER | E31: A | F31: 1500 | G31: 1041 | H31: =G31/F31*50 -> 34.7 | I31: 5 | J31: 5 | K31: 10 | L31: 8 | M31: 10 | N31: 10 | O31: =SUM(H31:N31) -> 82.7
A32: 27 | B32: 46018 | C32: S3 | D32: STRINGER | E32: A | F32: 1500 | G32: 335 | H32: =G32/F32*50 -> 11.166667 | I32: 5 | J32: 5 | K32: 10 | L32: 9 | M32: 10 | N32: 10 | O32: =SUM(H32:N32) -> 60.166667
A33: 28 | B33: 46019 | C33: W/O
A34: 29 | B34: 46020 | C34: S2 | D34: STRINGER | E34: A | F34: 1000 | G34: 441 | H34: =G34/F34*50 -> 22.05 | I34: 5 | J34: 5 | K34: 10 | L34: 9 | M34: 10 | N34: 10 | O34: =SUM(H34:N34) -> 71.05
A35: 30 | B35: 46021 | C35: S2 | D35: STRINGER | E35: A | F35: 1000 | G35: 478 | H35: =G35/F35*50 -> 23.9 | I35: 5 | J35: 0 | K35: 10 | L35: 10 | M35: 10 | N35: 10 | O35: =SUM(H35:N35) -> 68.9
A36: 31 | B36: 46022 | C36: S2 | D36: STRINGER | E36: A | F36: 1000 | G36: 510 | H36: =G36/F36*50 -> 25.5 | I36: 5 | J36: 5 | K36: 10 | L36: 10 | M36: 10 | N36: 10 | O36: =SUM(H36:N36) -> 75.5
G37: TOTAL | H37: =AVERAGE(H6:H35) -> 29.532051 | I37: =AVERAGE(I6:I35) -> 5 | J37: =AVERAGE(J6:J35) -> 4.6153846 | K37: =AVERAGE(K6:K35) -> 10 | L37: =AVERAGE(L6:L35) -> 9.1923077 | M37: =AVERAGE(M6:M35) -> 10 | N37: =AVERAGE(N6:N35) -> 10 | O37: =SUM(H37:N37) -> 78.339744

Sheet 15359
A1: Employee Performance Report | P1: REMARKS
A2: ID No | B2: Name | C2: Shift | D2: Stage | E2: Line | F2: Target | G2: Actual | H2: Matrix
A3: 15359 | B3: S.MANOJ
H4: 50 | I4: 5 | J4: 5 | K4: 10 | L4: 10 | M4: 10 | N4: 10 | O4: =SUM(H4:N4) -> 100
A5: Sl No | B5: Date | H5: Prodn Performance | I5: Attendence | J5: Punchuality | K5: Rejections | L5: 5S | M5: Safety & PPE Usage | N5: Disclipline | O5: Total
A6: 1 | B6: 45992 | C6: AB | I6: 5
A7: 2 | B7: 45993 | C7: S3 | D7: STRINGER | E7: A | F7: 1000 | G7: 693 | H7: =G7/F7*50 -> 34.65 | I7: 5 | J7: 5 | K7: 10 | L7: 9 | M7: 10 | N7: 10 | O7: =SUM(H7:N7) -> 83.65
A8: 3 | B8: 45994 | C8: S3 | D8: STRINGER | E8: A | F8: 1000 | G8: 698 | H8: =G8/F8*50 -> 34.9 | I8: 5 | J8: 5 | K8: 10 | L8: 10 | M8: 10 | N8: 10 | O8: =SUM(H8:N8) -> 84.9
A9: 4 | B9: 45995 | C9: S3 | D9: STRINGER | E9: A | F9: 1000 | G9: 714 | H9: =G9/F9*50 -> 35.7 | I9: 5 | J9: 5 | K9: 10 | L9: 7 | M9: 10 | N9: 10 | O9: =SUM(H9:N9) -> 82.7
A10: 5 | B10: 45996 | C10: AB | I10: 5
A11: 6 | B11: 45997 | C11: AB | I11: 5
A12: 7 | B12: 45998 | C12: W/O
A13: 8 | B13: 45999 | C13: AB | I13: 5
A14: 9 | B14: 46000 | C14: AB | I14: 5
A15: 10 | B15: 46001 | C15: AB | I15: 5
A16: 11 | B16: 46002 | C16: AB | I16: 5
A17: 12 | B17: 46003 | C17: W/O
A18: 13 | B18: 46004 | C18: S1 | D18: STRINGER | E18: A | F18: 1500 | G18: 921 | H18: =G18/F18*50 -> 30.7 | I18: 5 | J18: 5 | K18: 10 | L18: 9 | M18: 10 | N18: 10 | O18: =SUM(H18:N18) -> 79.7
A19: 14 | B19: 46005 | C19: S1 | D19: STRINGER | E19: A | F19: 1500 | G19: 387 | H19: =G19/F19*50 -> 12.9 | I19: 5 | J19: 5 | K19: 10 | L19: 9 | M19: 10 | N19: 10 | O19: =SUM(H19:N19) -> 61.9
A20: 15 | B20: 46006 | C20: S1 | D20: STRINGER | E20: A | F20: 1000 | G20: 599 | H20: =G20/F20*50 -> 29.95 | I20: 5 | J20: 5 | K20: 10 | L20: 8 | M20: 10 | N20: 10 | O20: =SUM(H20:N20) -> 77.95
A21: 16 | B21: 46007 | C21: S1 | D21: STRINGER | E21: A | F21: 513 | G21: 513 | H21: =G21/F21*50 -> 50 | I21: 5 | J21: 5 | K21: 10 | L21: 8 | M21: 10 | N21: 10 | O21: =SUM(H21:N21) -> 98 | P21: Display not working
A22: 17 | B22: 46008 | C22: S1 | D22: STRINGER | E22: A | F22: 1000 | G22: 682 | H22: =G22/F22*50 -> 34.1 | I22: 5 | J22: 5 | K22: 10 | L22: 10 | M22: 10 | N22: 10 | O22: =SUM(H22:N22) -> 84.1
A23: 18 | B23: 46009 | C23: S1 | D23: STRINGER | E23: A | F23: 1000 | G23: 765 | H23: =G23/F23*50 -> 38.25 | I23: 5 | J23: 5 | K23: 10 | L23: 10 | M23: 10 | N23: 10 | O23: =SUM(H23:N23) -> 88.25
A24: 19 | B24: 46010 | C24: S1 | D24: STRINGER | E24: A | F24: 1085 | G24: 1085 | H24: =G24/F24*50 -> 50 | I24: 5 | J24: 5 | K24: 10 | L24: 9 | M24: 10 | N24: 10 | O24: =SUM(H24:N24) -> 99 | P24: Aside stopped due to IR lamp issue
A25: 20 | B25: 46011 | C25: W/O
A26: 21 | B26: 46012 | C26: S3 | D26: STRINGER | E26: A | F26: 1500 | G26: 882 | H26: =G26/F26*50 -> 29.4 | I26: 5 | J26: 5 | K26: 10 | L26: 9 | M26: 10 | N26: 10 | O26: =SUM(H26:N26) -> 78.4
A27: 22 | B27: 46013 | C27: S3 | D27: STRINGER | E27: A | F27: 1000 | G27: 0 | H27: =G27/F27*50 -> 0 | I27: 5 | J27: 5 | K27: 10 | L27: 10 | M27: 10 | N27: 10 | O27: =SUM(H27:N27) -> 50
A28: 23 | B28: 46014 | C28: S3 | D28: STRINGER | E28: A | F28: 1000 | G28: 510 | H28: =G28/F28*50 -> 25.5 | I28: 5 | J28: 5 | K28: 10 | L28: 10 | M28: 10 | N28: 10 | O28: =SUM(H28:N28) -> 75.5
A29: 24 | B29: 46015 | C29: S3 | D29: STRINGER | E29: A | F29: 1000 | G29: 650 | H29: =G29/F29*50 -> 32.5 | I29: 5 | J29: 5 | K29: 10 | L29: 9 | M29: 10 | N29: 10 | O29: =SUM(H29:N29) -> 81.5
A30: 25 | B30: 46016 | C30: S3 | D30: STRINGER | E30: A | F30: 1000 | G30: 743 | H30: =G30/F30*50 -> 37.15 | I30: 5 | J30: 5 | K30: 10 | L30: 10 | M30: 10 | N30: 10 | O30: =SUM(H30:N30) -> 87.15
A31: 26 | B31: 46017 | C31: S3 | D31: STRINGER | E31: A | F31: 1500 | G31: 1041 | H31: =G31/F31*50 -> 34.7 | I31: 5 | J31: 5 | K31: 10 | L31: 8 | M31: 10 | N31: 10 | O31: =SUM(H31:N31) -> 82.7
A32: 27 | B32: 46018 | C32: S3 | D32: STRINGER | E32: A | F32: 1500 | G32: 335 | H32: =G32/F32*50 -> 11.166667 | I32: 5 | J32: 5 | K32: 10 | L32: 9 | M32: 10 | N32: 10 | O32: =SUM(H32:N32) -> 60.166667
A33: 28 | B33: 46019 | C33: W/O
A34: 29 | B34: 46020 | C34: S2 | D34: STRINGER | E34: A | F34: 1000 | G34: 441 | H34: =G34/F34*50 -> 22.05 | I34: 5 | J34: 5 | K34: 10 | L34: 9 | M34: 10 | N34: 10 | O34: =SUM(H34:N34) -> 71.05
A35: 30 | B35: 46021 | C35: S2 | D35: STRINGER | E35: A | F35: 1000 | G35: 478 | H35: =G35/F35*50 -> 23.9 | I35: 5 | J35: 5 | K35: 10 | L35: 10 | M35: 10 | N35: 10 | O35: =SUM(H35:N35) -> 73.9
A36: 31 | B36: 46022 | C36: S2 | D36: STRINGER | E36: A | F36: 1000 | G36: 510 | H36: =G36/F36*50 -> 25.5 | I36: 5 | J36: 5 | K36: 10 | L36: 10 | M36: 10 | N36: 10 | O36: =SUM(H36:N36) -> 75.5
G37: TOTAL | H37: =AVERAGE(H6:H35) -> 29.869298 | I37: =AVERAGE(I6:I35) -> 5 | J37: =AVERAGE(J6:J35) -> 5 | K37: =AVERAGE(K6:K35) -> 10 | L37: =AVERAGE(L6:L35) -> 9.1052632 | M37: =AVERAGE(M6:M35) -> 10 | N37: =AVERAGE(N6:N35) -> 10 | O37: =SUM(H37:N37) -> 78.974561

Sheet 15096
A1: Employee Performance Report | P1: REMARKS
A2: ID No | B2: Name | C2: Shift | D2: Stage | E2: Line | F2: Target | G2: Actual | H2: Matrix
A3: 15096 | B3: SUMAN SAMADAR
H4: 50 | I4: 5 | J4: 5 | K4: 10 | L4: 10 | M4: 10 | N4: 10 | O4: =SUM(H4:N4) -> 100
A5: Sl No | B5: Date | H5: Prodn Performance | I5: Attendence | J5: Punchuality | K5: Rejections | L5: 5S | M5: Safety & PPE Usage | N5: Disclipline | O5: Total
A6: 1 | B6: 45992 | C6: AB | I6: 5
A7: 2 | B7: 45993 | C7: AB | I7: 5
A8: 3 | B8: 45994 | C8: AB | I8: 5
A9: 4 | B9: 45995 | C9: AB | I9: 5
A10: 5 | B10: 45996 | C10: AB | I10: 5
A11: 6 | B11: 45997 | C11: AB | I11: 5
A12: 7 | B12: 45998 | C12: W/O
A13: 8 | B13: 45999 | C13: AB | I13: 5
A14: 9 | B14: 46000 | C14: AB | I14: 5
A15: 10 | B15: 46001 | C15: AB | I15: 5
A16: 11 | B16: 46002 | C16: AB | I16: 5
A17: 12 | B17: 46003 | C17: W/O
A18: 13 | B18: 46004 | C18: AB | I18: 5
A19: 14 | B19: 46005 | C19: AB | I19: 5
A20: 15 | B20: 46006 | C20: AB | I20: 5
A21: 16 | B21: 46007 | C21: AB | I21: 5
A22: 17 | B22: 46008 | C22: AB | I22: 5
A23: 18 | B23: 46009 | C23: AB | I23: 5
A24: 19 | B24: 46010 | C24: AB | I24: 5
A25: 20 | B25: 46011 | C25: W/O
A26: 21 | B26: 46012 | C26: S3 | D26: STRINGER | E26: A | F26: 1500 | G26: 882 | H26: =G26/F26*50 -> 29.4 | I26: 5 | J26: 5 | K26: 10 | L26: 9 | M26: 10 | N26: 10 | O26: =SUM(H26:N26) -> 78.4
A27: 22 | B27: 46013 | C27: S3 | D27: STRINGER | E27: A | F27: 1000 | G27: 0 | H27: =G27/F27*50 -> 0 | I27: 5 | J27: 5 | K27: 10 | L27: 10 | M27: 10 | N27: 10 | O27: =SUM(H27:N27) -> 50
A28: 23 | B28: 46014 | C28: S3 | D28: STRINGER | E28: A | F28: 1000 | G28: 510 | H28: =G28/F28*50 -> 25.5 | I28: 5 | J28: 5 | K28: 10 | L28: 10 | M28: 10 | N28: 10 | O28: =SUM(H28:N28) -> 75.5
A29: 24 | B29: 46015 | C29: S3 | D29: STRINGER | E29: A | F29: 1000 | G29: 650 | H29: =G29/F29*50 -> 32.5 | I29: 5 | J29: 5 | K29: 10 | L29: 9 | M29: 10 | N29: 10 | O29: =SUM(H29:N29) -> 81.5
A30: 25 | B30: 46016 | C30: S3 | D30: STRINGER | E30: A | F30: 1000 | G30: 743 | H30: =G30/F30*50 -> 37.15 | I30: 5 | J30: 5 | K30: 10 | L30: 10 | M30: 10 | N30: 10 | O30: =SUM(H30:N30) -> 87.15
A31: 26 | B31: 46017 | C31: S3 | D31: STRINGER | E31: A | F31: 1500 | G31: 1041 | H31: =G31/F31*50 -> 34.7 | I31: 5 | J31: 5 | K31: 10 | L31: 8 | M31: 10 | N31: 10 | O31: =SUM(H31:N31) -> 82.7
A32: 27 | B32: 46018 | C32: S3 | D32: STRINGER | E32: A | F32: 1500 | G32: 335 | H32: =G32/F32*50 -> 11.166667 | I32: 5 | J32: 5 | K32: 10 | L32: 9 | M32: 10 | N32: 10 | O32: =SUM(H32:N32) -> 60.166667
A33: 28 | B33: 46019 | C33: W/O
A34: 29 | B34: 46020 | C34: AB | I34: 5
A35: 30 | B35: 46021 | C35: S2 | D35: STRINGER | E35: A | F35: 1000 | G35: 478 | H35: =G35/F35*50 -> 23.9 | I35: 5 | J35: 5 | K35: 10 | L35: 10 | M35: 10 | N35: 10 | O35: =SUM(H35:N35) -> 73.9
A36: 31 | B36: 46022 | C36: S2 | D36: STRINGER | E36: A | F36: 1000 | G36: 510 | H36: =G36/F36*50 -> 25.5 | I36: 5 | J36: 5 | K36: 10 | L36: 10 | M36: 10 | N36: 10 | O36: =SUM(H36:N36) -> 75.5
G37: TOTAL | H37: =AVERAGE(H6:H35) -> 24.289583 | I37: =AVERAGE(I6:I35) -> 5 | J37: =AVERAGE(J6:J35) -> 5 | K37: =AVERAGE(K6:K35) -> 10 | L37: =AVERAGE(L6:L35) -> 9.375 | M37: =AVERAGE(M6:M35) -> 10 | N37: =AVERAGE(N6:N35) -> 10 | O37: =SUM(H37:N37) -> 73.664583

Sheet 15098
A1: Employee Performance Report | P1: REMARKS
A2: ID No | B2: Name | C2: Shift | D2: Stage | E2: Line | F2: Target | G2: Actual | H2: Matrix
A3: 15098 | B3: DARSHAN KUMAR
H4: 50 | I4: 5 | J4: 5 | K4: 10 | L4: 10 | M4: 10 | N4: 10 | O4: =SUM(H4:N4) -> 100
A5: Sl No | B5: Date | H5: Prodn Performance | I5: Attendence | J5: Punchuality | K5: Rejections | L5: 5S | M5: Safety & PPE Usage | N5: Disclipline | O5: Total
A6: 1 | B6: 45992 | C6: S3 | D6: BUSSING | E6: A | F6: 1000 | G6: 670 | H6: =G6/F6*50 -> 33.5 | I6: 5 | J6: 5 | K6: 10 | L6: 10 | M6: 10 | N6: 10 | O6: =SUM(H6:N6) -> 83.5
A7: 2 | B7: 45993 | C7: S3 | D7: BUSSING | E7: A | F7: 1000 | G7: 705 | H7: =G7/F7*50 -> 35.25 | I7: 5 | J7: 5 | K7: 10 | L7: 9 | M7: 10 | N7: 10 | O7: =SUM(H7:N7) -> 84.25
A8: 3 | B8: 45994 | C8: S3 | D8: BUSSING | E8: A | F8: 1000 | G8: 805 | H8: =G8/F8*50 -> 40.25 | I8: 5 | J8: 5 | K8: 10 | L8: 10 | M8: 10 | N8: 10 | O8: =SUM(H8:N8) -> 90.25
A9: 4 | B9: 45995 | C9: S3 | D9: BUSSING | E9: A | F9: 1000 | G9: 755 | H9: =G9/F9*50 -> 37.75 | I9: 5 | J9: 5 | K9: 10 | L9: 7 | M9: 10 | N9: 10 | O9: =SUM(H9:N9) -> 84.75
A10: 5 | B10: 45996 | C10: S3 | D10: BUSSING | E10: A | F10: 1500 | G10: 1037 | H10: =G10/F10*50 -> 34.566667 | I10: 5 | J10: 5 | K10: 10 | L10: 9 | M10: 10 | N10: 10 | O10: =SUM(H10:N10) -> 83.566667
A11: 6 | B11: 45997 | C11: S3 | D11: BUSSING | E11: A | F11: 1500 | G11: 182 | H11: =G11/F11*50 -> 6.0666667 | I11: 5 | J11: 5 | K11: 10 | L11: 9 | M11: 10 | N11: 10 | O11: =SUM(H11:N11) -> 55.066667
A12: 7 | B12: 45998 | C12: W/O
A13: 8 | B13: 45999 | C13: S2 | D13: BUSSING | E13: A | F13: 1000 | G13: 740 | H13: =G13/F13*50 -> 37 | I13: 5 | J13: 5 | K13: 10 | L13: 9 | M13: 10 | N13: 10 | O13: =SUM(H13:N13) -> 86
A14: 9 | B14: 46000 | C14: S2 | D14: BUSSING | E14: A | F14: 1000 | G14: 665 | H14: =G14/F14*50 -> 33.25 | I14: 5 | J14: 5 | K14: 10 | L14: 10 | M14: 10 | N14: 10 | O14: =SUM(H14:N14) -> 83.25
A15: 10 | B15: 46001 | C15: S2 | D15: BUSSING | E15: A | F15: 1000 | G15: 630 | H15: =G15/F15*50 -> 31.5 | I15: 5 | J15: 5 | K15: 10 | L15: 10 | M15: 10 | N15: 10 | O15: =SUM(H15:N15) -> 81.5
A16: 11 | B16: 46002 | C16: S2 | D16: BUSSING | E16: A | F16: 1000 | G16: 577 | H16: =G16/F16*50 -> 28.85 | I16: 5 | J16: 5 | K16: 10 | L16: 9 | M16: 10 | N16: 10 | O16: =SUM(H16:N16) -> 77.85
A17: 12 | B17: 46003 | C17: W/O
A18: 13 | B18: 46004 | C18: S1 | D18: BUSSING | E18: A | F18: 1500 | G18: 915 | H18: =G18/F18*50 -> 30.5 | I18: 5 | J18: 5 | K18: 10 | L18: 9 | M18: 10 | N18: 10 | O18: =SUM(H18:N18) -> 79.5
A19: 14 | B19: 46005 | C19: S1 | D19: BUSSING | E19: A | F19: 1500 | G19: 400 | H19: =G19/F19*50 -> 13.333333 | I19: 5 | J19: 5 | K19: 10 | L19: 9 | M19: 10 | N19: 10 | O19: =SUM(H19:N19) -> 62.333333
A20: 15 | B20: 46006 | C20: S1 | D20: BUSSING | E20: A | F20: 1000 | G20: 577 | H20: =G20/F20*50 -> 28.85 | I20: 5 | J20: 5 | K20: 10 | L20: 8 | M20: 10 | N20: 10 | O20: =SUM(H20:N20) -> 76.85
A21: 16 | B21: 46007 | C21: S1 | D21: BUSSING | E21: A | F21: 1000 | G21: 430 | H21: =G21/F21*50 -> 21.5 | I21: 5 | J21: 5 | K21: 10 | L21: 8 | M21: 10 | N21: 10 | O21: =SUM(H21:N21) -> 69.5
A22: 17 | B22: 46008 | C22: S1 | D22: BUSSING | E22: A | F22: 1000 | G22: 725 | H22: =G22/F22*50 -> 36.25 | I22: 5 | J22: 5 | K22: 10 | L22: 10 | M22: 10 | N22: 10 | O22: =SUM(H22:N22) -> 86.25
A23: 18 | B23: 46009 | C23: S1 | D23: BUSSING | E23: A | F23: 1000 | G23: 700 | H23: =G23/F23*50 -> 35 | I23: 5 | J23: 5 | K23: 10 | L23: 10 | M23: 10 | N23: 10 | O23: =SUM(H23:N23) -> 85
A24: 19 | B24: 46010 | C24: S1 | D24: BUSSING | E24: A | F24: 1500 | G24: 1112 | H24: =G24/F24*50 -> 37.066667 | I24: 5 | J24: 5 | K24: 10 | L24: 9 | M24: 10 | N24: 10 | O24: =SUM(H24:N24) -> 86.066667
A25: 20 | B25: 46011 | C25: W/O
A26: 21 | B26: 46012 | C26: S3 | D26: BUSSING | E26: A | F26: 1500 | G26: 915 | H26: =G26/F26*50 -> 30.5 | I26: 5 | J26: 5 | K26: 10 | L26: 9 | M26: 10 | N26: 10 | O26: =SUM(H26:N26) -> 79.5
A27: 22 | B27: 46013 | C27: S3 | D27: BUSSING | E27: A | F27: 1000 | G27: 0 | H27: =G27/F27*50 -> 0 | I27: 5 | J27: 5 | K27: 10 | L27: 10 | M27: 10 | N27: 10 | O27: =SUM(H27:N27) -> 50
A28: 23 | B28: 46014 | C28: S3 | D28: BUSSING | E28: A | F28: 1000 | G28: 550 | H28: =G28/F28*50 -> 27.5 | I28: 5 | J28: 5 | K28: 10 | L28: 10 | M28: 10 | N28: 10 | O28: =SUM(H28:N28) -> 77.5
A29: 24 | B29: 46015 | C29: S3 | D29: BUSSING | E29: A | F29: 1000 | G29: 625 | H29: =G29/F29*50 -> 31.25 | I29: 5 | J29: 5 | K29: 10 | L29: 9 | M29: 10 | N29: 10 | O29: =SUM(H29:N29) -> 80.25
A30: 25 | B30: 46016 | C30: S3 | D30: BUSSING | E30: A | F30: 1000 | G30: 725 | H30: =G30/F30*50 -> 36.25 | I30: 5 | J30: 5 | K30: 10 | L30: 10 | M30: 10 | N30: 10 | O30: =SUM(H30:N30) -> 86.25
A31: 26 | B31: 46017 | C31: S3 | D31: BUSSING | E31: A | F31: 1500 | G31: 1010 | H31: =G31/F31*50 -> 33.666667 | I31: 5 | J31: 5 | K31: 10 | L31: 8 | M31: 10 | N31: 10 | O31: =SUM(H31:N31) -> 81.666667
A32: 27 | B32: 46018 | C32: S3 | D32: BUSSING | E32: A | F32: 270 | G32: 270 | H32: =G32/F32*50 -> 50 | I32: 5 | J32: 5 | K32: 10 | L32: 9 | M32: 10 | N32: 10 | O32: =SUM(H32:N32) -> 99 | P32: Heat shield sensor heating and dry soldering issue
A33: 28 | B33: 46019 | C33: W/O
A34: 29 | B34: 46020 | C34: S2 | D34: BUSSING | E34: A | F34: 1000 | G34: 450 | H34: =G34/F34*50 -> 22.5 | I34: 5 | J34: 5 | K34: 10 | L34: 9 | M34: 10 | N34: 10 | O34: =SUM(H34:N34) -> 71.5
A35: 30 | B35: 46021 | C35: S2 | D35: BUSSING | E35: A | F35: 1000 | G35: 480 | H35: =G35/F35*50 -> 24 | I35: 5 | J35: 5 | K35: 10 | L35: 10 | M35: 10 | N35: 10 | O35: =SUM(H35:N35) -> 74
A36: 31 | B36: 46022 | C36: S2 | D36: BUSSING | E36: A | F36: 1000 | G36: 685 | H36: =G36/F36*50 -> 34.25 | I36: 5 | J36: 5 | K36: 10 | L36: 10 | M36: 10 | N36: 10 | O36: =SUM(H36:N36) -> 84.25
G37: TOTAL | H37: =AVERAGE(H6:H35) -> 29.851923 | I37: =AVERAGE(I6:I35) -> 5 | J37: =AVERAGE(J6:J35) -> 5 | K37: =AVERAGE(K6:K35) -> 10 | L37: =AVERAGE(L6:L35) -> 9.1923077 | M37: =AVERAGE(M6:M35) -> 10 | N37: =AVERAGE(N6:N35) -> 10 | O37: =SUM(H37:N37) -> 79.044231

Sheet 15529
A1: Employee Performance Report | P1: REMARKS
A2: ID No | B2: Name | C2: Shift | D2: Stage | E2: Line | F2: Target | G2: Actual | H2: Matrix
A3: 15529 | B3: SRINIVAS V
H4: 50 | I4: 5 | J4: 5 | K4: 10 | L4: 10 | M4: 10 | N4: 10 | O4: =SUM(H4:N4) -> 100
A5: Sl No | B5: Date | H5: Prodn Performance | I5: Attendence | J5: Punchuality | K5: Rejections | L5: 5S | M5: Safety & PPE Usage | N5: Disclipline | O5: Total
A6: 1 | B6: 45992 | C6: S3 | D6: TAPING | E6: A | F6: 1000 | G6: 670 | H6: =G6/F6*50 -> 33.5 | I6: 5 | J6: 5 | K6: 10 | L6: 10 | M6: 10 | N6: 10 | O6: =SUM(H6:N6) -> 83.5
A7: 2 | B7: 45993 | C7: S3 | D7: TAPING | E7: A | F7: 1000 | G7: 705 | H7: =G7/F7*50 -> 35.25 | I7: 5 | J7: 5 | K7: 10 | L7: 9 | M7: 10 | N7: 10 | O7: =SUM(H7:N7) -> 84.25
A8: 3 | B8: 45994 | C8: S3 | D8: TAPING | E8: A | F8: 1000 | G8: 805 | H8: =G8/F8*50 -> 40.25 | I8: 5 | J8: 5 | K8: 10 | L8: 10 | M8: 10 | N8: 10 | O8: =SUM(H8:N8) -> 90.25
A9: 4 | B9: 45995 | C9: S3 | D9: TAPING | E9: A | F9: 1000 | G9: 755 | H9: =G9/F9*50 -> 37.75 | I9: 5 | J9: 5 | K9: 10 | L9: 7 | M9: 10 | N9: 10 | O9: =SUM(H9:N9) -> 84.75
A10: 5 | B10: 45996 | C10: S3 | D10: TAPING | E10: A | F10: 1500 | G10: 1037 | H10: =G10/F10*50 -> 34.566667 | I10: 5 | J10: 5 | K10: 10 | L10: 9 | M10: 10 | N10: 10 | O10: =SUM(H10:N10) -> 83.566667
A11: 6 | B11: 45997 | C11: S3 | D11: TAPING | E11: A | F11: 1500 | G11: 182 | H11: =G11/F11*50 -> 6.0666667 | I11: 5 | J11: 5 | K11: 10 | L11: 9 | M11: 10 | N11: 10 | O11: =SUM(H11:N11) -> 55.066667
A12: 7 | B12: 45998 | C12: W/O
A13: 8 | B13: 45999 | C13: S2 | D13: TAPING | E13: A | F13: 1000 | G13: 740 | H13: =G13/F13*50 -> 37 | I13: 5 | J13: 5 | K13: 10 | L13: 9 | M13: 10 | N13: 10 | O13: =SUM(H13:N13) -> 86
A14: 9 | B14: 46000 | C14: S2 | D14: TAPING | E14: A | F14: 1000 | G14: 665 | H14: =G14/F14*50 -> 33.25 | I14: 5 | J14: 5 | K14: 10 | L14: 10 | M14: 10 | N14: 10 | O14: =SUM(H14:N14) -> 83.25
A15: 10 | B15: 46001 | C15: AB | I15: 5
A16: 11 | B16: 46002 | C16: S2 | D16: TAPING | E16: A | F16: 1000 | G16: 577 | H16: =G16/F16*50 -> 28.85 | I16: 5 | J16: 5 | K16: 10 | L16: 9 | M16: 10 | N16: 10 | O16: =SUM(H16:N16) -> 77.85
A17: 12 | B17: 46003 | C17: W/O
A18: 13 | B18: 46004 | C18: S1 | D18: TAPING | E18: A | F18: 1500 | G18: 915 | H18: =G18/F18*50 -> 30.5 | I18: 5 | J18: 5 | K18: 10 | L18: 9 | M18: 10 | N18: 10 | O18: =SUM(H18:N18) -> 79.5
A19: 14 | B19: 46005 | C19: S1 | D19: TAPING | E19: A | F19: 1500 | G19: 400 | H19: =G19/F19*50 -> 13.333333 | I19: 5 | J19: 5 | K19: 10 | L19: 9 | M19: 10 | N19: 10 | O19: =SUM(H19:N19) -> 62.333333
A20: 15 | B20: 46006 | C20: S1 | D20: TAPING | E20: A | F20: 1000 | G20: 577 | H20: =G20/F20*50 -> 28.85 | I20: 5 | J20: 5 | K20: 10 | L20: 8 | M20: 10 | N20: 10 | O20: =SUM(H20:N20) -> 76.85
A21: 16 | B21: 46007 | C21: S1 | D21: TAPING | E21: A | F21: 1000 | G21: 430 | H21: =G21/F21*50 -> 21.5 | I21: 5 | J21: 5 | K21: 10 | L21: 8 | M21: 10 | N21: 10 | O21: =SUM(H21:N21) -> 69.5
A22: 17 | B22: 46008 | C22: S1 | D22: TAPING | E22: A | F22: 1000 | G22: 725 | H22: =G22/F22*50 -> 36.25 | I22: 5 | J22: 5 | K22: 10 | L22: 10 | M22: 10 | N22: 10 | O22: =SUM(H22:N22) -> 86.25
A23: 18 | B23: 46009 | C23: S1 | D23: TAPING | E23: A | F23: 1000 | G23: 700 | H23: =G23/F23*50 -> 35 | I23: 5 | J23: 5 | K23: 10 | L23: 10 | M23: 10 | N23: 10 | O23: =SUM(H23:N23) -> 85
A24: 19 | B24: 46010 | C24: S1 | D24: TAPING | E24: A | F24: 1500 | G24: 1112 | H24: =G24/F24*50 -> 37.066667 | I24: 5 | J24: 5 | K24: 10 | L24: 9 | M24: 10 | N24: 10 | O24: =SUM(H24:N24) -> 86.066667
A25: 20 | B25: 46011 | C25: W/O
A26: 21 | B26: 46012 | C26: S3 | D26: TAPING | E26: A | F26: 1500 | G26: 915 | H26: =G26/F26*50 -> 30.5 | I26: 5 | J26: 5 | K26: 10 | L26: 9 | M26: 10 | N26: 10 | O26: =SUM(H26:N26) -> 79.5
A27: 22 | B27: 46013 | C27: S3 | D27: TAPING | E27: A | F27: 1000 | G27: 0 | H27: =G27/F27*50 -> 0 | I27: 5 | J27: 5 | K27: 10 | L27: 10 | M27: 10 | N27: 10 | O27: =SUM(H27:N27) -> 50
A28: 23 | B28: 46014 | C28: S3 | D28: TAPING | E28: A | F28: 1000 | G28: 550 | H28: =G28/F28*50 -> 27.5 | I28: 5 | J28: 5 | K28: 10 | L28: 10 | M28: 10 | N28: 10 | O28: =SUM(H28:N28) -> 77.5
A29: 24 | B29: 46015 | C29: S3 | D29: TAPING | E29: A | F29: 1000 | G29: 625 | H29: =G29/F29*50 -> 31.25 | I29: 5 | J29: 5 | K29: 10 | L29: 9 | M29: 10 | N29: 10 | O29: =SUM(H29:N29) -> 80.25
A30: 25 | B30: 46016 | C30: S3 | D30: TAPING | E30: A | F30: 1000 | G30: 725 | H30: =G30/F30*50 -> 36.25 | I30: 5 | J30: 5 | K30: 10 | L30: 10 | M30: 10 | N30: 10 | O30: =SUM(H30:N30) -> 86.25
A31: 26 | B31: 46017 | C31: S3 | D31: TAPING | E31: A | F31: 1500 | G31: 1010 | H31: =G31/F31*50 -> 33.666667 | I31: 5 | J31: 5 | K31: 10 | L31: 8 | M31: 10 | N31: 10 | O31: =SUM(H31:N31) -> 81.666667
A32: 27 | B32: 46018 | C32: S3 | D32: TAPING | E32: A | F32: 270 | G32: 270 | H32: =G32/F32*50 -> 50 | I32: 5 | J32: 5 | K32: 10 | L32: 9 | M32: 10 | N32: 10 | O32: =SUM(H32:N32) -> 99 | P32: Heat shield sensor heating and dry soldering issue
A33: 28 | B33: 46019 | C33: W/O
A34: 29 | B34: 46020 | C34: S2 | D34: TAPING | E34: A | F34: 1000 | G34: 450 | H34: =G34/F34*50 -> 22.5 | I34: 5 | J34: 5 | K34: 10 | L34: 9 | M34: 10 | N34: 10 | O34: =SUM(H34:N34) -> 71.5
A35: 30 | B35: 46021 | C35: S2 | D35: TAPING | E35: A | F35: 1000 | G35: 480 | H35: =G35/F35*50 -> 24 | I35: 5 | J35: 5 | K35: 10 | L35: 10 | M35: 10 | N35: 10 | O35: =SUM(H35:N35) -> 74
A36: 31 | B36: 46022 | C36: S2 | D36: TAPING | E36: A | F36: 1000 | G36: 685 | H36: =G36/F36*50 -> 34.25 | I36: 5 | J36: 5 | K36: 10 | L36: 10 | M36: 10 | N36: 10 | O36: =SUM(H36:N36) -> 84.25
G37: TOTAL | H37: =AVERAGE(H6:H35) -> 29.786 | I37: =AVERAGE(I6:I35) -> 5 | J37: =AVERAGE(J6:J35) -> 5 | K37: =AVERAGE(K6:K35) -> 10 | L37: =AVERAGE(L6:L35) -> 9.16 | M37: =AVERAGE(M6:M35) -> 10 | N37: =AVERAGE(N6:N35) -> 10 | O37: =SUM(H37:N37) -> 78.946

Sheet 15530
A1: Employee Performance Report | P1: REMARKS
A2: ID No | B2: Name | C2: Shift | D2: Stage | E2: Line | F2: Target | G2: Actual | H2: Matrix
A3: 15530 | B3: POOJARAPPA
H4: 50 | I4: 5 | J4: 5 | K4: 10 | L4: 10 | M4: 10 | N4: 10 | O4: =SUM(H4:N4) -> 100
A5: Sl No | B5: Date | H5: Prodn Performance | I5: Attendence | J5: Punchuality | K5: Rejections | L5: 5S | M5: Safety & PPE Usage | N5: Disclipline | O5: Total
A6: 1 | B6: 45992 | C6: S3 | D6: REWORK | E6: A | F6: 1000 | G6: 670 | H6: =G6/F6*50 -> 33.5 | I6: 5 | J6: 5 | K6: 10 | L6: 10 | M6: 10 | N6: 10 | O6: =SUM(H6:N6) -> 83.5
A7: 2 | B7: 45993 | C7: S3 | D7: REWORK | E7: A | F7: 1000 | G7: 705 | H7: =G7/F7*50 -> 35.25 | I7: 5 | J7: 5 | K7: 10 | L7: 9 | M7: 10 | N7: 10 | O7: =SUM(H7:N7) -> 84.25
A8: 3 | B8: 45994 | C8: S3 | D8: REWORK | E8: A | F8: 1000 | G8: 805 | H8: =G8/F8*50 -> 40.25 | I8: 5 | J8: 5 | K8: 10 | L8: 10 | M8: 10 | N8: 10 | O8: =SUM(H8:N8) -> 90.25
A9: 4 | B9: 45995 | C9: S3 | D9: REWORK | E9: A | F9: 1000 | G9: 755 | H9: =G9/F9*50 -> 37.75 | I9: 5 | J9: 5 | K9: 10 | L9: 7 | M9: 10 | N9: 10 | O9: =SUM(H9:N9) -> 84.75
A10: 5 | B10: 45996 | C10: S3 | D10: REWORK | E10: A | F10: 1500 | G10: 1037 | H10: =G10/F10*50 -> 34.566667 | I10: 5 | J10: 5 | K10: 10 | L10: 9 | M10: 10 | N10: 10 | O10: =SUM(H10:N10) -> 83.566667
A11: 6 | B11: 45997 | C11: S3 | D11: REWORK | E11: A | F11: 1500 | G11: 182 | H11: =G11/F11*50 -> 6.0666667 | I11: 5 | J11: 5 | K11: 10 | L11: 9 | M11: 10 | N11: 10 | O11: =SUM(H11:N11) -> 55.066667
A12: 7 | B12: 45998 | C12: W/O
A13: 8 | B13: 45999 | C13: S2 | D13: REWORK | E13: A | F13: 1000 | G13: 740 | H13: =G13/F13*50 -> 37 | I13: 5 | J13: 5 | K13: 10 | L13: 9 | M13: 10 | N13: 10 | O13: =SUM(H13:N13) -> 86
A14: 9 | B14: 46000 | C14: S2 | D14: REWORK | E14: A | F14: 1000 | G14: 665 | H14: =G14/F14*50 -> 33.25 | I14: 5 | J14: 5 | K14: 10 | L14: 10 | M14: 10 | N14: 10 | O14: =SUM(H14:N14) -> 83.25
A15: 10 | B15: 46001 | C15: S2 | D15: REWORK | E15: A | F15: 1000 | G15: 630 | H15: =G15/F15*50 -> 31.5 | I15: 5 | J15: 5 | K15: 10 | L15: 10 | M15: 10 | N15: 10 | O15: =SUM(H15:N15) -> 81.5
A16: 11 | B16: 46002 | C16: S2 | D16: REWORK | E16: A | F16: 1000 | G16: 577 | H16: =G16/F16*50 -> 28.85 | I16: 5 | J16: 5 | K16: 10 | L16: 9 | M16: 10 | N16: 10 | O16: =SUM(H16:N16) -> 77.85
A17: 12 | B17: 46003 | C17: W/O
A18: 13 | B18: 46004 | C18: S1 | D18: REWORK | E18: A | F18: 1500 | G18: 915 | H18: =G18/F18*50 -> 30.5 | I18: 5 | J18: 5 | K18: 10 | L18: 9 | M18: 10 | N18: 10 | O18: =SUM(H18:N18) -> 79.5
A19: 14 | B19: 46005 | C19: S1 | D19: REWORK | E19: A | F19: 1500 | G19: 400 | H19: =G19/F19*50 -> 13.333333 | I19: 5 | J19: 5 | K19: 10 | L19: 9 | M19: 10 | N19: 10 | O19: =SUM(H19:N19) -> 62.333333
A20: 15 | B20: 46006 | C20: S1 | D20: REWORK | E20: A | F20: 1000 | G20: 577 | H20: =G20/F20*50 -> 28.85 | I20: 5 | J20: 5 | K20: 10 | L20: 8 | M20: 10 | N20: 10 | O20: =SUM(H20:N20) -> 76.85
A21: 16 | B21: 46007 | C21: S1 | D21: REWORK | E21: A | F21: 1000 | G21: 430 | H21: =G21/F21*50 -> 21.5 | I21: 5 | J21: 5 | K21: 10 | L21: 8 | M21: 10 | N21: 10 | O21: =SUM(H21:N21) -> 69.5
A22: 17 | B22: 46008 | C22: S1 | D22: REWORK | E22: A | F22: 1000 | G22: 725 | H22: =G22/F22*50 -> 36.25 | I22: 5 | J22: 5 | K22: 10 | L22: 10 | M22: 10 | N22: 10 | O22: =SUM(H22:N22) -> 86.25
A23: 18 | B23: 46009 | C23: AB | I23: 5
A24: 19 | B24: 46010 | C24: S1 | D24: REWORK | E24: A | F24: 1500 | G24: 1112 | H24: =G24/F24*50 -> 37.066667 | I24: 5 | J24: 5 | K24: 10 | L24: 9 | M24: 10 | N24: 10 | O24: =SUM(H24:N24) -> 86.066667
A25: 20 | B25: 46011 | C25: W/O
A26: 21 | B26: 46012 | C26: S3 | D26: REWORK | E26: A | F26: 1500 | G26: 915 | H26: =G26/F26*50 -> 30.5 | I26: 5 | J26: 5 | K26: 10 | L26: 9 | M26: 10 | N26: 10 | O26: =SUM(H26:N26) -> 79.5
A27: 22 | B27: 46013 | C27: S3 | D27: REWORK | E27: A | F27: 1000 | G27: 0 | H27: =G27/F27*50 -> 0 | I27: 5 | J27: 5 | K27: 10 | L27: 10 | M27: 10 | N27: 10 | O27: =SUM(H27:N27) -> 50
A28: 23 | B28: 46014 | C28: S3 | D28: REWORK | E28: A | F28: 1000 | G28: 550 | H28: =G28/F28*50 -> 27.5 | I28: 5 | J28: 5 | K28: 10 | L28: 10 | M28: 10 | N28: 10 | O28: =SUM(H28:N28) -> 77.5
A29: 24 | B29: 46015 | C29: S3 | D29: REWORK | E29: A | F29: 1000 | G29: 625 | H29: =G29/F29*50 -> 31.25 | I29: 5 | J29: 5 | K29: 10 | L29: 9 | M29: 10 | N29: 10 | O29: =SUM(H29:N29) -> 80.25
A30: 25 | B30: 46016 | C30: S3 | D30: REWORK | E30: A | F30: 1000 | G30: 725 | H30: =G30/F30*50 -> 36.25 | I30: 5 | J30: 5 | K30: 10 | L30: 10 | M30: 10 | N30: 10 | O30: =SUM(H30:N30) -> 86.25
A31: 26 | B31: 46017 | C31: S3 | D31: REWORK | E31: A | F31: 1500 | G31: 1010 | H31: =G31/F31*50 -> 33.666667 | I31: 5 | J31: 5 | K31: 10 | L31: 8 | M31: 10 | N31: 10 | O31: =SUM(H31:N31) -> 81.666667
A32: 27 | B32: 46018 | C32: S3 | D32: REWORK | E32: A | F32: 270 | G32: 270 | H32: =G32/F32*50 -> 50 | I32: 5 | J32: 5 | K32: 10 | L32: 9 | M32: 10 | N32: 10 | O32: =SUM(H32:N32) -> 99 | P32: Heat shield sensor heating and dry soldering issue
A33: 28 | B33: 46019 | C33: W/O
A34: 29 | B34: 46020 | C34: S2 | D34: REWORK | E34: A | F34: 1000 | G34: 450 | H34: =G34/F34*50 -> 22.5 | I34: 5 | J34: 5 | K34: 10 | L34: 9 | M34: 10 | N34: 10 | O34: =SUM(H34:N34) -> 71.5
A35: 30 | B35: 46021 | C35: S2 | D35: REWORK | E35: A | F35: 1000 | G35: 480 | H35: =G35/F35*50 -> 24 | I35: 5 | J35: 5 | K35: 10 | L35: 10 | M35: 10 | N35: 10 | O35: =SUM(H35:N35) -> 74
A36: 31 | B36: 46022 | C36: S2 | D36: REWORK | E36: A | F36: 1000 | G36: 685 | H36: =G36/F36*50 -> 34.25 | I36: 5 | J36: 5 | K36: 10 | L36: 10 | M36: 10 | N36: 10 | O36: =SUM(H36:N36) -> 84.25
G37: TOTAL | H37: =AVERAGE(H6:H35) -> 29.646 | I37: =AVERAGE(I6:I35) -> 5 | J37: =AVERAGE(J6:J35) -> 5 | K37: =AVERAGE(K6:K35) -> 10 | L37: =AVERAGE(L6:L35) -> 9.16 | M37: =AVERAGE(M6:M35) -> 10 | N37: =AVERAGE(N6:N35) -> 10 | O37: =SUM(H37:N37) -> 78.806

Sheet 15326
A1: Employee Performance Report | P1: REMARKS
A2: ID No | B2: Name | C2: Shift | D2: Stage | E2: Line | F2: Target | G2: Actual | H2: Matrix
A3: 15326 | B3: MADHU SUDAN
H4: 50 | I4: 5 | J4: 5 | K4: 10 | L4: 10 | M4: 10 | N4: 10 | O4: =SUM(H4:N4) -> 100
A5: Sl No | B5: Date | H5: Prodn Performance | I5: Attendence | J5: Punchuality | K5: Rejections | L5: 5S | M5: Safety & PPE Usage | N5: Disclipline | O5: Total
A6: 1 | B6: 45992 | C6: S3 | D6: BUSSING | E6: A | F6: 1000 | G6: 670 | H6: =G6/F6*50 -> 33.5 | I6: 5 | J6: 5 | K6: 10 | L6: 10 | M6: 10 | N6: 10 | O6: =SUM(H6:N6) -> 83.5
A7: 2 | B7: 45993 | C7: S3 | D7: BUSSING | E7: A | F7: 1000 | G7: 705 | H7: =G7/F7*50 -> 35.25 | I7: 5 | J7: 5 | K7: 10 | L7: 9 | M7: 10 | N7: 10 | O7: =SUM(H7:N7) -> 84.25
A8: 3 | B8: 45994 | C8: S3 | D8: BUSSING | E8: A | F8: 1000 | G8: 805 | H8: =G8/F8*50 -> 40.25 | I8: 5 | J8: 5 | K8: 10 | L8: 10 | M8: 10 | N8: 10 | O8: =SUM(H8:N8) -> 90.25
A9: 4 | B9: 45995 | C9: S3 | D9: BUSSING | E9: A | F9: 1000 | G9: 755 | H9: =G9/F9*50 -> 37.75 | I9: 5 | J9: 5 | K9: 10 | L9: 7 | M9: 10 | N9: 10 | O9: =SUM(H9:N9) -> 84.75
A10: 5 | B10: 45996 | C10: S3 | D10: BUSSING | E10: A | F10: 1500 | G10: 1037 | H10: =G10/F10*50 -> 34.566667 | I10: 5 | J10: 5 | K10: 10 | L10: 9 | M10: 10 | N10: 10 | O10: =SUM(H10:N10) -> 83.566667
A11: 6 | B11: 45997 | C11: S3 | D11: BUSSING | E11: A | F11: 1500 | G11: 182 | H11: =G11/F11*50 -> 6.0666667 | I11: 5 | J11: 5 | K11: 10 | L11: 9 | M11: 10 | N11: 10 | O11: =SUM(H11:N11) -> 55.066667
A12: 7 | B12: 45998 | C12: W/O
A13: 8 | B13: 45999 | C13: S2 | D13: BUSSING | E13: A | F13: 1000 | G13: 740 | H13: =G13/F13*50 -> 37 | I13: 5 | J13: 5 | K13: 10 | L13: 9 | M13: 10 | N13: 10 | O13: =SUM(H13:N13) -> 86
A14: 9 | B14: 46000 | C14: S2 | D14: BUSSING | E14: A | F14: 1000 | G14: 665 | H14: =G14/F14*50 -> 33.25 | I14: 5 | J14: 5 | K14: 10 | L14: 10 | M14: 10 | N14: 10 | O14: =SUM(H14:N14) -> 83.25
A15: 10 | B15: 46001 | C15: S2 | D15: BUSSING | E15: A | F15: 1000 | G15: 630 | H15: =G15/F15*50 -> 31.5 | I15: 5 | J15: 5 | K15: 10 | L15: 10 | M15: 10 | N15: 10 | O15: =SUM(H15:N15) -> 81.5
A16: 11 | B16: 46002 | C16: S2 | D16: BUSSING | E16: A | F16: 1000 | G16: 577 | H16: =G16/F16*50 -> 28.85 | I16: 5 | J16: 5 | K16: 10 | L16: 9 | M16: 10 | N16: 10 | O16: =SUM(H16:N16) -> 77.85
A17: 12 | B17: 46003 | C17: W/O
A18: 13 | B18: 46004 | C18: S1 | D18: BUSSING | E18: A | F18: 1500 | G18: 915 | H18: =G18/F18*50 -> 30.5 | I18: 5 | J18: 5 | K18: 10 | L18: 9 | M18: 10 | N18: 10 | O18: =SUM(H18:N18) -> 79.5
A19: 14 | B19: 46005 | C19: S1 | D19: BUSSING | E19: A | F19: 1500 | G19: 400 | H19: =G19/F19*50 -> 13.333333 | I19: 5 | J19: 5 | K19: 10 | L19: 9 | M19: 10 | N19: 10 | O19: =SUM(H19:N19) -> 62.333333
A20: 15 | B20: 46006 | C20: S1 | D20: BUSSING | E20: A | F20: 1000 | G20: 577 | H20: =G20/F20*50 -> 28.85 | I20: 5 | J20: 5 | K20: 10 | L20: 8 | M20: 10 | N20: 10 | O20: =SUM(H20:N20) -> 76.85
A21: 16 | B21: 46007 | C21: S1 | D21: BUSSING | E21: A | F21: 1000 | G21: 430 | H21: =G21/F21*50 -> 21.5 | I21: 5 | J21: 5 | K21: 10 | L21: 8 | M21: 10 | N21: 10 | O21: =SUM(H21:N21) -> 69.5
A22: 17 | B22: 46008 | C22: S1 | D22: BUSSING | E22: A | F22: 1000 | G22: 725 | H22: =G22/F22*50 -> 36.25 | I22: 5 | J22: 5 | K22: 10 | L22: 10 | M22: 10 | N22: 10 | O22: =SUM(H22:N22) -> 86.25
A23: 18 | B23: 46009 | C23: S1 | D23: BUSSING | E23: A | F23: 1000 | G23: 700 | H23: =G23/F23*50 -> 35 | I23: 5 | J23: 5 | K23: 10 | L23: 10 | M23: 10 | N23: 10 | O23: =SUM(H23:N23) -> 85
A24: 19 | B24: 46010 | C24: S1 | D24: BUSSING | E24: A | F24: 1500 | G24: 1112 | H24: =G24/F24*50 -> 37.066667 | I24: 5 | J24: 5 | K24: 10 | L24: 9 | M24: 10 | N24: 10 | O24: =SUM(H24:N24) -> 86.066667
A25: 20 | B25: 46011 | C25: W/O
A26: 21 | B26: 46012 | C26: S3 | D26: BUSSING | E26: A | F26: 1500 | G26: 915 | H26: =G26/F26*50 -> 30.5 | I26: 5 | J26: 5 | K26: 10 | L26: 9 | M26: 10 | N26: 10 | O26: =SUM(H26:N26) -> 79.5
A27: 22 | B27: 46013 | C27: S3 | D27: BUSSING | E27: A | F27: 1000 | G27: 0 | H27: =G27/F27*50 -> 0 | I27: 5 | J27: 5 | K27: 10 | L27: 10 | M27: 10 | N27: 10 | O27: =SUM(H27:N27) -> 50
A28: 23 | B28: 46014 | C28: S3 | D28: BUSSING | E28: A | F28: 1000 | G28: 550 | H28: =G28/F28*50 -> 27.5 | I28: 5 | J28: 5 | K28: 10 | L28: 10 | M28: 10 | N28: 10 | O28: =SUM(H28:N28) -> 77.5
A29: 24 | B29: 46015 | C29: S3 | D29: BUSSING | E29: A | F29: 1000 | G29: 625 | H29: =G29/F29*50 -> 31.25 | I29: 5 | J29: 5 | K29: 10 | L29: 9 | M29: 10 | N29: 10 | O29: =SUM(H29:N29) -> 80.25
A30: 25 | B30: 46016 | C30: S3 | D30: BUSSING | E30: A | F30: 1000 | G30: 725 | H30: =G30/F30*50 -> 36.25 | I30: 5 | J30: 5 | K30: 10 | L30: 10 | M30: 10 | N30: 10 | O30: =SUM(H30:N30) -> 86.25
A31: 26 | B31: 46017 | C31: S3 | D31: BUSSING | E31: A | F31: 1500 | G31: 1010 | H31: =G31/F31*50 -> 33.666667 | I31: 5 | J31: 5 | K31: 10 | L31: 8 | M31: 10 | N31: 10 | O31: =SUM(H31:N31) -> 81.666667
A32: 27 | B32: 46018 | C32: S3 | D32: BUSSING | E32: A | F32: 270 | G32: 270 | H32: =G32/F32*50 -> 50 | I32: 5 | J32: 5 | K32: 10 | L32: 9 | M32: 10 | N32: 10 | O32: =SUM(H32:N32) -> 99 | P32: Heat shield sensor heating and dry soldering issue
A33: 28 | B33: 46019 | C33: W/O
A34: 29 | B34: 46020 | C34: S2 | D34: BUSSING | E34: A | F34: 1000 | G34: 450 | H34: =G34/F34*50 -> 22.5 | I34: 5 | J34: 5 | K34: 10 | L34: 9 | M34: 10 | N34: 10 | O34: =SUM(H34:N34) -> 71.5
A35: 30 | B35: 46021 | C35: S2 | D35: BUSSING | E35: A | F35: 1000 | G35: 480 | H35: =G35/F35*50 -> 24 | I35: 5 | J35: 5 | K35: 10 | L35: 10 | M35: 10 | N35: 10 | O35: =SUM(H35:N35) -> 74
A36: 31 | B36: 46022 | C36: S2 | D36: BUSSING | E36: A | F36: 1000 | G36: 685 | H36: =G36/F36*50 -> 34.25 | I36: 5 | J36: 5 | K36: 10 | L36: 10 | M36: 10 | N36: 10 | O36: =SUM(H36:N36) -> 84.25
G37: TOTAL | H37: =AVERAGE(H6:H35) -> 29.851923 | I37: =AVERAGE(I6:I35) -> 5 | J37: =AVERAGE(J6:J35) -> 5 | K37: =AVERAGE(K6:K35) -> 10 | L37: =AVERAGE(L6:L35) -> 9.1923077 | M37: =AVERAGE(M6:M35) -> 10 | N37: =AVERAGE(N6:N35) -> 10 | O37: =SUM(H37:N37) -> 79.044231

Sheet 15338
A1: Employee Performance Report | P1: REMARKS
A2: ID No | B2: Name | C2: Shift | D2: Stage | E2: Line | F2: Target | G2: Actual | H2: Matrix
A3: 15338 | B3: PRASHANTH R
H4: 50 | I4: 5 | J4: 5 | K4: 10 | L4: 10 | M4: 10 | N4: 10 | O4: =SUM(H4:N4) -> 100
A5: Sl No | B5: Date | H5: Prodn Performance | I5: Attendence | J5: Punchuality | K5: Rejections | L5: 5S | M5: Safety & PPE Usage | N5: Disclipline | O5: Total
A6: 1 | B6: 45992 | C6: S3 | D6: LAM | E6: A | F6: 635 | G6: 635 | H6: =G6/F6*50 -> 50 | I6: 5 | J6: 5 | K6: 10 | L6: 10 | M6: 10 | N6: 10 | O6: =SUM(H6:N6) -> 100 | P6: Frequently C/D side frame dent and module broke issue
A7: 2 | B7: 45993 | C7: S3 | D7: LAM | E7: A | F7: 1000 | G7: 772 | H7: =G7/F7*50 -> 38.6 | I7: 5 | J7: 5 | K7: 10 | L7: 9 | M7: 10 | N7: 10 | O7: =SUM(H7:N7) -> 87.6
A8: 3 | B8: 45994 | C8: S3 | D8: LAM | E8: A | F8: 1000 | G8: 805 | H8: =G8/F8*50 -> 40.25 | I8: 5 | J8: 5 | K8: 10 | L8: 10 | M8: 10 | N8: 10 | O8: =SUM(H8:N8) -> 90.25
